<?xml version="1.0"?>
<robot name="custom_bot">
  <link name="base_link">
    <visual><geometry><box size="0.4 0.2 0.1"/></geometry><material name="blue"><color rgba="0 0.5 1 1"/></material></visual>
    <collision><geometry><box size="0.4 0.2 0.1"/></geometry></collision>
    <inertial><mass value="5.0"/><inertia ixx="0.01" ixy="0" ixz="0" iyy="0.01" iyz="0" izz="0.01"/></inertial>
  </link>

  <link name="left_wheel">
    <visual><geometry><cylinder radius="0.05" length="0.04"/></geometry><material name="black"><color rgba="0 0 0 1"/></material></visual>
    <collision><geometry><cylinder radius="0.05" length="0.04"/></geometry></collision>
    <inertial><mass value="0.5"/><inertia ixx="0.001" ixy="0" ixz="0" iyy="0.001" iyz="0" izz="0.001"/></inertial>
  </link>
  <joint name="left_wheel_joint" type="continuous">
    <parent link="base_link"/><child link="left_wheel"/>
    <origin xyz="0 0.12 -0.05" rpy="-1.5707 0 0"/><axis xyz="0 0 1"/>
  </joint>

  <link name="right_wheel">
    <visual><geometry><cylinder radius="0.05" length="0.04"/></geometry><material name="black"><color rgba="0 0 0 1"/></material></visual>
    <collision><geometry><cylinder radius="0.05" length="0.04"/></geometry></collision>
    <inertial><mass value="0.5"/><inertia ixx="0.001" ixy="0" ixz="0" iyy="0.001" iyz="0" izz="0.001"/></inertial>
  </link>
  <joint name="right_wheel_joint" type="continuous">
    <parent link="base_link"/><child link="right_wheel"/>
    <origin xyz="0 -0.12 -0.05" rpy="-1.5707 0 0"/><axis xyz="0 0 1"/>
  </joint>

  <link name="caster">
    <visual><geometry><sphere radius="0.049"/></geometry><material name="black"/></visual>
    <collision><geometry><sphere radius="0.049"/></geometry></collision>
    <inertial><mass value="0.2"/><inertia ixx="0.001" ixy="0" ixz="0" iyy="0.001" iyz="0" izz="0.001"/></inertial>
  </link>
  <joint name="caster_joint" type="fixed">
    <parent link="base_link"/><child link="caster"/>
    <origin xyz="0.15 0 -0.05" rpy="0 0 0"/>
  </joint>
  <gazebo reference="caster"><mu1>0.0</mu1><mu2>0.0</mu2></gazebo>

  <link name="lidar_link">
    <visual><geometry><cylinder radius="0.04" length="0.05"/></geometry><material name="red"><color rgba="1 0 0 1"/></material></visual>
  </link>
  <joint name="lidar_joint" type="fixed">
    <parent link="base_link"/><child link="lidar_link"/>
    <origin xyz="0 0 0.08" rpy="0 0 0"/>
  </joint>

  <link name="camera_link">
    <visual>
      <geometry><box size="0.03 0.03 0.03"/></geometry>
      <material name="green"><color rgba="0 1 0 1"/></material>
    </visual>
  </link>
  <joint name="camera_joint" type="fixed">
    <parent link="base_link"/><child link="camera_link"/>
    <origin xyz="0.2 0 0.05" rpy="0 0 0"/>
  </joint>

  <link name="camera_link_optical"></link>
  <joint name="camera_optical_joint" type="fixed">
    <parent link="camera_link"/><child link="camera_link_optical"/>
    <origin xyz="0 0 -0.05" rpy="-1.5707 0 -1.5707"/>
  </joint>

  <gazebo reference="lidar_link">
    <sensor type="ray" name="my_lidar">
      <visualize>true</visualize>
      <update_rate>10</update_rate>
      <ray>
        <scan><horizontal><samples>360</samples><resolution>1</resolution><min_angle>-3.14</min_angle><max_angle>3.14</max_angle></horizontal></scan>
        <range><min>0.15</min><max>8.0</max></range>
      </ray>
      <plugin name="gazebo_ros_laser_controller" filename="libgazebo_ros_ray_sensor.so">
        <ros><remapping>~/out:=scan</remapping></ros>
        <output_type>sensor_msgs/LaserScan</output_type>
        <frame_name>lidar_link</frame_name>
      </plugin>
    </sensor>
  </gazebo>

  <gazebo reference="camera_link">
    <sensor type="camera" name="my_camera">
      <update_rate>30.0</update_rate> <camera name="head">
        <horizontal_fov>1.3962634</horizontal_fov> <image>
          <width>640</width>
          <height>480</height>
          <format>R8G8B8</format>
        </image>
        <clip><near>0.02</near><far>300</far></clip>
      </camera>
      <plugin name="camera_controller" filename="libgazebo_ros_camera.so">
        <ros>
          <remapping>image_raw:=camera/image_raw</remapping>
          <remapping>camera_info:=camera/camera_info</remapping>
        </ros>
        <frame_name>camera_link_optical</frame_name>
      </plugin>
    </sensor>
  </gazebo>

  <gazebo>
    <plugin name="diff_drive" filename="libgazebo_ros_diff_drive.so">
      <left_joint>left_wheel_joint</left_joint>
      <right_joint>right_wheel_joint</right_joint>
      <wheel_separation>0.24</wheel_separation>
      <wheel_diameter>0.1</wheel_diameter>
      <command_topic>cmd_vel</command_topic>
      <publish_odom>true</publish_odom>
      <publish_odom_tf>true</publish_odom_tf>
      <publish_wheel_tf>true</publish_wheel_tf>
      <odometry_topic>odom</odometry_topic>
      <odometry_frame>odom</odometry_frame>
      <robot_base_frame>base_link</robot_base_frame>
    </plugin>
  </gazebo>
</robot>
